[2024-11-05T23:37:59.549-0500] {taskinstance.py:1159} INFO - Dependencies all met for dep_context=non-requeueable deps ti=<TaskInstance: data_pipeline_with_custom_email_alerts1.load_and_merge_data manual__2024-11-06T04:30:57.325826+00:00 [queued]>
[2024-11-05T23:37:59.555-0500] {taskinstance.py:1159} INFO - Dependencies all met for dep_context=requeueable deps ti=<TaskInstance: data_pipeline_with_custom_email_alerts1.load_and_merge_data manual__2024-11-06T04:30:57.325826+00:00 [queued]>
[2024-11-05T23:37:59.555-0500] {taskinstance.py:1361} INFO - Starting attempt 2 of 2
[2024-11-05T23:37:59.663-0500] {taskinstance.py:1382} INFO - Executing <Task(PythonOperator): load_and_merge_data> on 2024-11-06 04:30:57.325826+00:00
[2024-11-05T23:37:59.667-0500] {standard_task_runner.py:57} INFO - Started process 94649 to run task
[2024-11-05T23:37:59.669-0500] {standard_task_runner.py:84} INFO - Running: ['airflow', 'tasks', 'run', 'data_pipeline_with_custom_email_alerts1', 'load_and_merge_data', 'manual__2024-11-06T04:30:57.325826+00:00', '--job-id', '550', '--raw', '--subdir', 'DAGS_FOLDER/try1.py', '--cfg-path', '/tmp/tmppnpijdi8']
[2024-11-05T23:37:59.670-0500] {standard_task_runner.py:85} INFO - Job 550: Subtask load_and_merge_data
[2024-11-05T23:37:59.777-0500] {task_command.py:416} INFO - Running <TaskInstance: data_pipeline_with_custom_email_alerts1.load_and_merge_data manual__2024-11-06T04:30:57.325826+00:00 [running]> on host mrudula-OMEN-by-HP-Laptop
[2024-11-05T23:37:59.879-0500] {taskinstance.py:1662} INFO - Exporting env vars: AIRFLOW_CTX_DAG_OWNER='airflow' AIRFLOW_CTX_DAG_ID='data_pipeline_with_custom_email_alerts1' AIRFLOW_CTX_TASK_ID='load_and_merge_data' AIRFLOW_CTX_EXECUTION_DATE='2024-11-06T04:30:57.325826+00:00' AIRFLOW_CTX_TRY_NUMBER='2' AIRFLOW_CTX_DAG_RUN_ID='manual__2024-11-06T04:30:57.325826+00:00'
[2024-11-05T23:37:59.932-0500] {taskinstance.py:1937} ERROR - Task failed with exception
Traceback (most recent call last):
  File "/home/mrudula/airflow/lib/python3.10/site-packages/airflow/operators/python.py", line 192, in execute
    return_value = self.execute_callable()
  File "/home/mrudula/airflow/lib/python3.10/site-packages/airflow/operators/python.py", line 209, in execute_callable
    return self.python_callable(*self.op_args, **self.op_kwargs)
  File "/home/mrudula/airflow/dags/try1.py", line 283, in load_and_merge_data
    merged_df_final = pd.merge(
  File "/home/mrudula/airflow/lib/python3.10/site-packages/pandas/core/reshape/merge.py", line 152, in merge
    left_df = _validate_operand(left)
  File "/home/mrudula/airflow/lib/python3.10/site-packages/pandas/core/reshape/merge.py", line 2692, in _validate_operand
    raise TypeError(
TypeError: Can only merge Series or DataFrame objects, a <class 'NoneType'> was passed
[2024-11-05T23:37:59.935-0500] {taskinstance.py:1400} INFO - Marking task as FAILED. dag_id=data_pipeline_with_custom_email_alerts1, task_id=load_and_merge_data, execution_date=20241106T043057, start_date=20241106T043759, end_date=20241106T043759
[2024-11-05T23:38:00.236-0500] {standard_task_runner.py:104} ERROR - Failed to execute job 550 for task load_and_merge_data (Can only merge Series or DataFrame objects, a <class 'NoneType'> was passed; 94649)
[2024-11-05T23:38:00.282-0500] {local_task_job_runner.py:228} INFO - Task exited with return code 1
[2024-11-05T23:38:00.296-0500] {taskinstance.py:2778} INFO - 0 downstream tasks scheduled from follow-on schedule check
