[2024-11-05T23:29:47.170-0500] {taskinstance.py:1159} INFO - Dependencies all met for dep_context=non-requeueable deps ti=<TaskInstance: data_pipeline_with_custom_email_alerts1.load_and_merge_data manual__2024-11-06T04:24:04.710564+00:00 [queued]>
[2024-11-05T23:29:47.179-0500] {taskinstance.py:1159} INFO - Dependencies all met for dep_context=requeueable deps ti=<TaskInstance: data_pipeline_with_custom_email_alerts1.load_and_merge_data manual__2024-11-06T04:24:04.710564+00:00 [queued]>
[2024-11-05T23:29:47.179-0500] {taskinstance.py:1361} INFO - Starting attempt 2 of 2
[2024-11-05T23:29:47.333-0500] {taskinstance.py:1382} INFO - Executing <Task(PythonOperator): load_and_merge_data> on 2024-11-06 04:24:04.710564+00:00
[2024-11-05T23:29:47.338-0500] {standard_task_runner.py:57} INFO - Started process 92239 to run task
[2024-11-05T23:29:47.342-0500] {standard_task_runner.py:84} INFO - Running: ['airflow', 'tasks', 'run', 'data_pipeline_with_custom_email_alerts1', 'load_and_merge_data', 'manual__2024-11-06T04:24:04.710564+00:00', '--job-id', '501', '--raw', '--subdir', 'DAGS_FOLDER/try1.py', '--cfg-path', '/tmp/tmp7ts8tdxz']
[2024-11-05T23:29:47.344-0500] {standard_task_runner.py:85} INFO - Job 501: Subtask load_and_merge_data
[2024-11-05T23:29:47.475-0500] {task_command.py:416} INFO - Running <TaskInstance: data_pipeline_with_custom_email_alerts1.load_and_merge_data manual__2024-11-06T04:24:04.710564+00:00 [running]> on host mrudula-OMEN-by-HP-Laptop
[2024-11-05T23:29:47.590-0500] {taskinstance.py:1662} INFO - Exporting env vars: AIRFLOW_CTX_DAG_OWNER='airflow' AIRFLOW_CTX_DAG_ID='data_pipeline_with_custom_email_alerts1' AIRFLOW_CTX_TASK_ID='load_and_merge_data' AIRFLOW_CTX_EXECUTION_DATE='2024-11-06T04:24:04.710564+00:00' AIRFLOW_CTX_TRY_NUMBER='2' AIRFLOW_CTX_DAG_RUN_ID='manual__2024-11-06T04:24:04.710564+00:00'
[2024-11-05T23:29:47.674-0500] {taskinstance.py:1937} ERROR - Task failed with exception
Traceback (most recent call last):
  File "/home/mrudula/airflow/lib/python3.10/site-packages/airflow/operators/python.py", line 192, in execute
    return_value = self.execute_callable()
  File "/home/mrudula/airflow/lib/python3.10/site-packages/airflow/operators/python.py", line 209, in execute_callable
    return self.python_callable(*self.op_args, **self.op_kwargs)
  File "/home/mrudula/airflow/dags/try1.py", line 282, in load_and_merge_data
    merged_df_final = participantstatus_demographics_biospecimen_merged_cleaned.merge(motor_senses_merged_cleaned, on='PATNO', how='inner')
AttributeError: 'NoneType' object has no attribute 'merge'
[2024-11-05T23:29:47.678-0500] {taskinstance.py:1400} INFO - Marking task as FAILED. dag_id=data_pipeline_with_custom_email_alerts1, task_id=load_and_merge_data, execution_date=20241106T042404, start_date=20241106T042947, end_date=20241106T042947
[2024-11-05T23:29:47.816-0500] {standard_task_runner.py:104} ERROR - Failed to execute job 501 for task load_and_merge_data ('NoneType' object has no attribute 'merge'; 92239)
[2024-11-05T23:29:47.874-0500] {local_task_job_runner.py:228} INFO - Task exited with return code 1
[2024-11-05T23:29:47.892-0500] {taskinstance.py:2778} INFO - 0 downstream tasks scheduled from follow-on schedule check
