[2024-11-05T23:24:46.105-0500] {taskinstance.py:1159} INFO - Dependencies all met for dep_context=non-requeueable deps ti=<TaskInstance: data_pipeline_with_custom_email_alerts1.clean_preprocess_eda manual__2024-11-06T04:24:04.710564+00:00 [queued]>
[2024-11-05T23:24:46.113-0500] {taskinstance.py:1159} INFO - Dependencies all met for dep_context=requeueable deps ti=<TaskInstance: data_pipeline_with_custom_email_alerts1.clean_preprocess_eda manual__2024-11-06T04:24:04.710564+00:00 [queued]>
[2024-11-05T23:24:46.113-0500] {taskinstance.py:1361} INFO - Starting attempt 1 of 2
[2024-11-05T23:24:46.263-0500] {taskinstance.py:1382} INFO - Executing <Task(PythonOperator): clean_preprocess_eda> on 2024-11-06 04:24:04.710564+00:00
[2024-11-05T23:24:46.268-0500] {standard_task_runner.py:57} INFO - Started process 90795 to run task
[2024-11-05T23:24:46.273-0500] {standard_task_runner.py:84} INFO - Running: ['airflow', 'tasks', 'run', 'data_pipeline_with_custom_email_alerts1', 'clean_preprocess_eda', 'manual__2024-11-06T04:24:04.710564+00:00', '--job-id', '484', '--raw', '--subdir', 'DAGS_FOLDER/try1.py', '--cfg-path', '/tmp/tmp7eiuznfy']
[2024-11-05T23:24:46.274-0500] {standard_task_runner.py:85} INFO - Job 484: Subtask clean_preprocess_eda
[2024-11-05T23:24:46.398-0500] {task_command.py:416} INFO - Running <TaskInstance: data_pipeline_with_custom_email_alerts1.clean_preprocess_eda manual__2024-11-06T04:24:04.710564+00:00 [running]> on host mrudula-OMEN-by-HP-Laptop
[2024-11-05T23:24:46.648-0500] {taskinstance.py:1662} INFO - Exporting env vars: AIRFLOW_CTX_DAG_OWNER='airflow' AIRFLOW_CTX_DAG_ID='data_pipeline_with_custom_email_alerts1' AIRFLOW_CTX_TASK_ID='clean_preprocess_eda' AIRFLOW_CTX_EXECUTION_DATE='2024-11-06T04:24:04.710564+00:00' AIRFLOW_CTX_TRY_NUMBER='1' AIRFLOW_CTX_DAG_RUN_ID='manual__2024-11-06T04:24:04.710564+00:00'
[2024-11-05T23:24:46.658-0500] {taskinstance.py:1937} ERROR - Task failed with exception
Traceback (most recent call last):
  File "/home/mrudula/airflow/lib/python3.10/site-packages/airflow/operators/python.py", line 192, in execute
    return_value = self.execute_callable()
  File "/home/mrudula/airflow/lib/python3.10/site-packages/airflow/operators/python.py", line 209, in execute_callable
    return self.python_callable(*self.op_args, **self.op_kwargs)
  File "/home/mrudula/airflow/dags/try1.py", line 293, in clean_preprocess_eda
    data_final = data_final.drop_duplicates()
AttributeError: 'NoneType' object has no attribute 'drop_duplicates'
[2024-11-05T23:24:46.667-0500] {taskinstance.py:1400} INFO - Marking task as UP_FOR_RETRY. dag_id=data_pipeline_with_custom_email_alerts1, task_id=clean_preprocess_eda, execution_date=20241106T042404, start_date=20241106T042446, end_date=20241106T042446
[2024-11-05T23:24:46.847-0500] {standard_task_runner.py:104} ERROR - Failed to execute job 484 for task clean_preprocess_eda ('NoneType' object has no attribute 'drop_duplicates'; 90795)
[2024-11-05T23:24:46.885-0500] {local_task_job_runner.py:228} INFO - Task exited with return code 1
[2024-11-05T23:24:46.980-0500] {taskinstance.py:2778} INFO - 0 downstream tasks scheduled from follow-on schedule check
